Workbook

Sheet Bheights
A1: colony | B1: year | C1: Site | D1: track | E1: sample | F1: ccoldday | G1: warmday | H1: gulf | I1: height | J1: tf | K1: hname | L1: Bheight | M1: minage
A2: ala01 | B2: 2005 | C2: AlAqah | D2: t1 | E2: ala01_t1 | F2: 38 | G2: 303 | H2: oman | I2: 7 | J2: TRUE | K2: =CONCATENATE(A2, B2) -> ala012005 | L2: =VLOOKUP(K2,BheightCalcs!I$1:M$429, 5, FALSE) -> 2.12625 | M2: =VLOOKUP(A2, BheightCalcs!P$1:S$39, 4, FALSE) -> 8
A3: ala01 | B3: 2006 | C3: AlAqah | D3: t1 | E3: ala01_t1 | F3: 25 | G3: 294 | H3: oman | I3: 7 | J3: TRUE | K3: =CONCATENATE(A3, B3) -> ala012006 | L3: =VLOOKUP(K3,BheightCalcs!I$1:M$429, 5, FALSE) -> 2.5955 | M3: =VLOOKUP(A3, BheightCalcs!P$1:S$39, 4, FALSE) -> 8
A4: ala01 | B4: 2006 | C4: AlAqah | D4: t2 | E4: ala01_t2 | F4: 25 | G4: 294 | H4: oman | I4: 7 | J4: TRUE | K4: =CONCATENATE(A4, B4) -> ala012006 | L4: =VLOOKUP(K4,BheightCalcs!I$1:M$429, 5, FALSE) -> 2.5955 | M4: =VLOOKUP(A4, BheightCalcs!P$1:S$39, 4, FALSE) -> 8
A5: ala01 | B5: 2007 | C5: AlAqah | D5: t2 | E5: ala01_t2 | F5: 66 | G5: 286 | H5: oman | I5: 7 | J5: TRUE | K5: =CONCATENATE(A5, B5) -> ala012007 | L5: =VLOOKUP(K5,BheightCalcs!I$1:M$429, 5, FALSE) -> 3.3321 | M5: =VLOOKUP(A5, BheightCalcs!P$1:S$39, 4, FALSE) -> 8
A6: ala01 | B6: 2007 | C6: AlAqah | D6: t1 | E6: ala01_t1 | F6: 66 | G6: 286 | H6: oman | I6: 7 | J6: TRUE | K6: =CONCATENATE(A6, B6) -> ala012007 | L6: =VLOOKUP(K6,BheightCalcs!I$1:M$429, 5, FALSE) -> 3.3321 | M6: =VLOOKUP(A6, BheightCalcs!P$1:S$39, 4, FALSE) -> 8
A7: ala01 | B7: 2008 | C7: AlAqah | D7: t2 | E7: ala01_t2 | F7: 53 | G7: 299 | H7: oman | I7: 7 | J7: TRUE | K7: =CONCATENATE(A7, B7) -> ala012008 | L7: =VLOOKUP(K7,BheightCalcs!I$1:M$429, 5, FALSE) -> 3.94255 | M7: =VLOOKUP(A7, BheightCalcs!P$1:S$39, 4, FALSE) -> 8
A8: ala01 | B8: 2008 | C8: AlAqah | D8: t1 | E8: ala01_t1 | F8: 53 | G8: 299 | H8: oman | I8: 7 | J8: TRUE | K8: =CONCATENATE(A8, B8) -> ala012008 | L8: =VLOOKUP(K8,BheightCalcs!I$1:M$429, 5, FALSE) -> 3.94255 | M8: =VLOOKUP(A8, BheightCalcs!P$1:S$39, 4, FALSE) -> 8
A9: ala01 | B9: 2009 | C9: AlAqah | D9: t2 | E9: ala01_t2 | F9: 44 | G9: 288 | H9: oman | I9: 7 | J9: TRUE | K9: =CONCATENATE(A9, B9) -> ala012009 | L9: =VLOOKUP(K9,BheightCalcs!I$1:M$429, 5, FALSE) -> 4.4446 | M9: =VLOOKUP(A9, BheightCalcs!P$1:S$39, 4, FALSE) -> 8
A10: ala01 | B10: 2009 | C10: AlAqah | D10: t1 | E10: ala01_t1 | F10: 44 | G10: 288 | H10: oman | I10: 7 | J10: TRUE | K10: =CONCATENATE(A10, B10) -> ala012009 | L10: =VLOOKUP(K10,BheightCalcs!I$1:M$429, 5, FALSE) -> 4.4446 | M10: =VLOOKUP(A10, BheightCalcs!P$1:S$39, 4, FALSE) -> 8
A11: ala01 | B11: 2010 | C11: AlAqah | D11: t1 | E11: ala01_t1 | F11: 40 | G11: 282 | H11: oman | I11: 7 | J11: TRUE | K11: =CONCATENATE(A11, B11) -> ala012010 | L11: =VLOOKUP(K11,BheightCalcs!I$1:M$429, 5, FALSE) -> 5.00965 | M11: =VLOOKUP(A11, BheightCalcs!P$1:S$39, 4, FALSE) -> 8
A12: ala01 | B12: 2010 | C12: AlAqah | D12: t2 | E12: ala01_t2 | F12: 40 | G12: 282 | H12: oman | I12: 7 | J12: TRUE | K12: =CONCATENATE(A12, B12) -> ala012010 | L12: =VLOOKUP(K12,BheightCalcs!I$1:M$429, 5, FALSE) -> 5.00965 | M12: =VLOOKUP(A12, BheightCalcs!P$1:S$39, 4, FALSE) -> 8
A13: ala01 | B13: 2011 | C13: AlAqah | D13: t1 | E13: ala01_t1 | F13: 66 | G13: 284 | H13: oman | I13: 7 | J13: TRUE | K13: =CONCATENATE(A13, B13) -> ala012011 | L13: =VLOOKUP(K13,BheightCalcs!I$1:M$429, 5, FALSE) -> 5.5898 | M13: =VLOOKUP(A13, BheightCalcs!P$1:S$39, 4, FALSE) -> 8
... A759: sad22 | B759: 2013 | C759: Saadiyat | D759: t2 | E759: sad22_t2 | F759: 20 | G759: 299 | H759: gulf | I759: 7 | J759: TRUE | K759: =CONCATENATE(A759, B759) -> sad222013 | L759: =VLOOKUP(K759,BheightCalcs!I$1:M$429, 5, FALSE) -> 7 | M759: =VLOOKUP(A759, BheightCalcs!P$1:S$39, 4, FALSE) -> 9

Sheet BheightCalcs
G1: colony | H1: Row Labels | I1: newlab | J1: Average of extension | K1: Max of height | L1: jsjs | M1: Bheight | P1: colony | Q1: maxyear | R1: minyear | S1: minage
G2: ala01 | H2: 2005 | I2: =CONCATENATE(G2,H2) -> ala012005 | J2: 0.6155 | K2: 7 | L2: =L3-J3 -> 2.12625 | M2: 2.12625 | P2: ala01 | Q2: 2013 | R2: 2005 | S2: =Q2-R2 -> 8
A3: Row Labels | B3: Average of extension | C3: Max of height | G3: ala01 | H3: 2006 | I3: =CONCATENATE(G3,H3) -> ala012006 | J3: 0.46925 | K3: 7 | L3: =L4-J4 -> 2.5955 | M3: 2.5955 | P3: ala02 | Q3: 2013 | R3: 2010 | S3: =Q3-R3 -> 3
A4: ala01 | B4: 0.60958824 | C4: 7 | G4: ala01 | H4: 2007 | I4: =CONCATENATE(G4,H4) -> ala012007 | J4: 0.7366 | K4: 7 | L4: =L5-J5 -> 3.3321 | M4: 3.3321 | P4: ala08 | Q4: 2013 | R4: 2005 | S4: =Q4-R4 -> 8
A5: 2005 | B5: 0.6155 | C5: 7 | G5: ala01 | H5: 2008 | I5: =CONCATENATE(G5,H5) -> ala012008 | J5: 0.61045 | K5: 7 | L5: =L6-J6 -> 3.94255 | M5: 3.94255 | P5: ala10 | Q5: 2013 | R5: 2002 | S5: =Q5-R5 -> 11
A6: 2006 | B6: 0.46925 | C6: 7 | G6: ala01 | H6: 2009 | I6: =CONCATENATE(G6,H6) -> ala012009 | J6: 0.50205 | K6: 7 | L6: =L7-J7 -> 4.4446 | M6: 4.4446 | P6: ala12 | Q6: 2013 | R6: 2000 | S6: =Q6-R6 -> 13
A7: 2007 | B7: 0.7366 | C7: 7 | G7: ala01 | H7: 2010 | I7: =CONCATENATE(G7,H7) -> ala012010 | J7: 0.56505 | K7: 7 | L7: =L8-J8 -> 5.00965 | M7: 5.00965 | P7: ala14 | Q7: 2013 | R7: 2010 | S7: =Q7-R7 -> 3
A8: 2008 | B8: 0.61045 | C8: 7 | G8: ala01 | H8: 2011 | I8: =CONCATENATE(G8,H8) -> ala012011 | J8: 0.58015 | K8: 7 | L8: =L9-J9 -> 5.5898 | M8: 5.5898 | P8: ala21 | Q8: 2013 | R8: 2008 | S8: =Q8-R8 -> 5
A9: 2009 | B9: 0.50205 | C9: 7 | G9: ala01 | H9: 2012 | I9: =CONCATENATE(G9,H9) -> ala012012 | J9: 0.68115 | K9: 7 | L9: =K9-J10 -> 6.27095 | M9: 6.27095 | P9: del01 | Q9: 2013 | R9: 2004 | S9: =Q9-R9 -> 9
A10: 2010 | B10: 0.56505 | C10: 7 | G10: ala01 | H10: 2013 | I10: =CONCATENATE(G10,H10) -> ala012013 | J10: 0.72905 | K10: 7 | M10: 7 | P10: del07 | Q10: 2013 | R10: 2004 | S10: =Q10-R10 -> 9
A11: 2011 | B11: 0.58015 | C11: 7 | H11: ala02 | I11: =CONCATENATE(G11,H11) -> ala02 | J11: 1.1219375 | K11: 6 | M11: 6 | P11: del08 | Q11: 2013 | R11: 2005 | S11: =Q11-R11 -> 8
A12: 2012 | B12: 0.68115 | C12: 7 | G12: ala02 | H12: 2010 | I12: =CONCATENATE(G12,H12) -> ala022010 | J12: 1.04435 | K12: 6 | L12: =L13-J13 -> 2.5566 | M12: 2.5566 | P12: del09 | Q12: 2013 | R12: 2003 | S12: =Q12-R12 -> 10
A13: 2013 | B13: 0.72905 | C13: 7 | G13: ala02 | H13: 2011 | I13: =CONCATENATE(G13,H13) -> ala022011 | J13: 1.0822 | K13: 6 | L13: =L14-J14 -> 3.6388 | M13: 3.6388 | P13: del12 | Q13: 2013 | R13: 2004 | S13: =Q13-R13 -> 9
A14: ala02 | B14: 1.1219375 | C14: 6 | G14: ala02 | H14: 2012 | I14: =CONCATENATE(G14,H14) -> ala022012 | J14: 1.14275 | K14: 6 | L14: =K14-J15 -> 4.78155 | M14: 4.78155 | P14: del20 | Q14: 2013 | R14: 2002 | S14: =Q14-R14 -> 11
A15: 2010 | B15: 1.04435 | C15: 6 | G15: ala02 | H15: 2013 | I15: =CONCATENATE(G15,H15) -> ala022013 | J15: 1.21845 | K15: 6 | M15: 6 | P15: dib01 | Q15: 2013 | R15: 2000 | S15: =Q15-R15 -> 13
A16: 2011 | B16: 1.0822 | C16: 6 | H16: ala08 | I16: =CONCATENATE(G16,H16) -> ala08 | J16: 0.63654444 | K16: 8 | M16: 8 | P16: dib02 | Q16: 2013 | R16: 2003 | S16: =Q16-R16 -> 10
A17: 2012 | B17: 1.14275 | C17: 6 | G17: ala08 | H17: 2005 | I17: =CONCATENATE(G17,H17) -> ala082005 | J17: 0.78205 | K17: 8 | L17: =L18-J18 -> 3.05315 | M17: 3.05315 | P17: dib03 | Q17: 2013 | R17: 2005 | S17: =Q17-R17 -> 8
A18: 2013 | B18: 1.21845 | C18: 6 | G18: ala08 | H18: 2006 | I18: =CONCATENATE(G18,H18) -> ala082006 | J18: 0.56255 | K18: 8 | L18: =L19-J19 -> 3.6157 | M18: 3.6157 | P18: dib04 | Q18: 2013 | R18: 2000 | S18: =Q18-R18 -> 13
A19: ala08 | B19: 0.63654444 | C19: 8 | G19: ala08 | H19: 2007 | I19: =CONCATENATE(G19,H19) -> ala082007 | J19: 0.835 | K19: 8 | L19: =L20-J20 -> 4.4507 | M19: 4.4507 | P19: dib06 | Q19: 2013 | R19: 2004 | S19: =Q19-R19 -> 9
A20: 2005 | B20: 0.78205 | C20: 8 | G20: ala08 | H20: 2008 | I20: =CONCATENATE(G20,H20) -> ala082008 | J20: 0.47675 | K20: 8 | L20: =L21-J21 -> 4.92745 | M20: 4.92745 | P20: dib08 | Q20: 2013 | R20: 2004 | S20: =Q20-R20 -> 9
A21: 2006 | B21: 0.56255 | C21: 8 | G21: ala08 | H21: 2009 | I21: =CONCATENATE(G21,H21) -> ala082009 | J21: 0.81985 | K21: 8 | L21: =L22-J22 -> 5.7473 | M21: 5.7473 | P21: dib15 | Q21: 2013 | R21: 2008 | S21: =Q21-R21 -> 5
A22: 2007 | B22: 0.835 | C22: 8 | G22: ala08 | H22: 2010 | I22: =CONCATENATE(G22,H22) -> ala082010 | J22: 0.6483 | K22: 8 | L22: =L23-J23 -> 6.3956 | M22: 6.3956 | P22: dib16 | Q22: 2013 | R22: 2008 | S22: =Q22-R22 -> 5
A23: 2008 | B23: 0.47675 | C23: 8 | G23: ala08 | H23: 2011 | I23: =CONCATENATE(G23,H23) -> ala082011 | J23: 0.47425 | K23: 8 | L23: =L24-J24 -> 6.86985 | M23: 6.86985 | P23: ras04 | Q23: 2013 | R23: 2000 | S23: =Q23-R23 -> 13
A24: 2009 | B24: 0.81985 | C24: 8 | G24: ala08 | H24: 2012 | I24: =CONCATENATE(G24,H24) -> ala082012 | J24: 0.46165 | K24: 8 | L24: =K24-J25 -> 7.3315 | M24: 7.3315 | P24: ras07 | Q24: 2013 | R24: 2006 | S24: =Q24-R24 -> 7
A25: 2010 | B25: 0.6483 | C25: 8 | G25: ala08 | H25: 2013 | I25: =CONCATENATE(G25,H25) -> ala082013 | J25: 0.6685 | K25: 8 | M25: 8 | P25: ras09 | Q25: 2013 | R25: 2006 | S25: =Q25-R25 -> 7
A26: 2011 | B26: 0.47425 | C26: 8 | H26: ala10 | I26: =CONCATENATE(G26,H26) -> ala10 | J26: 0.57186957 | K26: 8.5 | M26: 8.5 | P26: ras11 | Q26: 2013 | R26: 2001 | S26: =Q26-R26 -> 12
A27: 2012 | B27: 0.46165 | C27: 8 | G27: ala10 | H27: 2002 | I27: =CONCATENATE(G27,H27) -> ala102002 | J27: 0.7265 | K27: 8.5 | L27: =L28-J28 -> 2.28675 | M27: 2.28675 | P27: ras12 | Q27: 2013 | R27: 2000 | S27: =Q27-R27 -> 13
A28: 2013 | B28: 0.6685 | C28: 8 | G28: ala10 | H28: 2003 | I28: =CONCATENATE(G28,H28) -> ala102003 | J28: 0.58275 | K28: 8.5 | L28: =L29-J29 -> 2.8695 | M28: 2.8695 | P28: ras13 | Q28: 2013 | R28: 2002 | S28: =Q28-R28 -> 11
A29: ala10 | B29: 0.57186957 | C29: 8.5 | G29: ala10 | H29: 2004 | I29: =CONCATENATE(G29,H29) -> ala102004 | J29: 0.80975 | K29: 8.5 | L29: =L30-J30 -> 3.67925 | M29: 3.67925 | P29: ras15 | Q29: 2013 | R29: 2004 | S29: =Q29-R29 -> 9
A30: 2002 | B30: 0.7265 | C30: 8.5 | G30: ala10 | H30: 2005 | I30: =CONCATENATE(G30,H30) -> ala102005 | J30: 0.53485 | K30: 8.5 | L30: =L31-J31 -> 4.2141 | M30: 4.2141 | P30: ras16 | Q30: 2013 | R30: 2003 | S30: =Q30-R30 -> 10
A31: 2003 | B31: 0.58275 | C31: 8.5 | G31: ala10 | H31: 2006 | I31: =CONCATENATE(G31,H31) -> ala102006 | J31: 0.5625 | K31: 8.5 | L31: =L32-J32 -> 4.7766 | M31: 4.7766 | P31: ras21 | Q31: 2013 | R31: 2003 | S31: =Q31-R31 -> 10
A32: 2004 | B32: 0.80975 | C32: 8.5 | G32: ala10 | H32: 2007 | I32: =CONCATENATE(G32,H32) -> ala102007 | J32: 0.5197 | K32: 8.5 | L32: =L33-J33 -> 5.2963 | M32: 5.2963 | P32: sad05 | Q32: 2013 | R32: 2003 | S32: =Q32-R32 -> 10
A33: 2005 | B33: 0.53485 | C33: 8.5 | G33: ala10 | H33: 2008 | I33: =CONCATENATE(G33,H33) -> ala102008 | J33: 0.42375 | K33: 8.5 | L33: =L34-J34 -> 5.72005 | M33: 5.72005 | P33: sad07 | Q33: 2013 | R33: 2002 | S33: =Q33-R33 -> 11
A34: 2006 | B34: 0.5625 | C34: 8.5 | G34: ala10 | H34: 2009 | I34: =CONCATENATE(G34,H34) -> ala102009 | J34: 0.56505 | K34: 8.5 | L34: =L35-J35 -> 6.2851 | M34: 6.2851 | P34: sad08 | Q34: 2013 | R34: 2001 | S34: =Q34-R34 -> 12
A35: 2007 | B35: 0.5197 | C35: 8.5 | G35: ala10 | H35: 2010 | I35: =CONCATENATE(G35,H35) -> ala102010 | J35: 0.6635 | K35: 8.5 | L35: =L36-J36 -> 6.9486 | M35: 6.9486 | P35: sad12 | Q35: 2013 | R35: 2000 | S35: =Q35-R35 -> 13
A36: 2008 | B36: 0.42375 | C36: 8.5 | G36: ala10 | H36: 2011 | I36: =CONCATENATE(G36,H36) -> ala102011 | J36: 0.47175 | K36: 8.5 | L36: =L37-J37 -> 7.42035 | M36: 7.42035 | P36: sad13 | Q36: 2013 | R36: 2002 | S36: =Q36-R36 -> 11
A37: 2009 | B37: 0.56505 | C37: 8.5 | G37: ala10 | H37: 2012 | I37: =CONCATENATE(G37,H37) -> ala102012 | J37: 0.6054 | K37: 8.5 | L37: =K37-J38 -> 8.02575 | M37: 8.02575 | P37: sad14 | Q37: 2013 | R37: 2010 | S37: =Q37-R37 -> 3
A38: 2010 | B38: 0.6635 | C38: 8.5 | G38: ala10 | H38: 2013 | I38: =CONCATENATE(G38,H38) -> ala102013 | J38: 0.47425 | K38: 8.5 | M38: 8.5 | P38: sad15 | Q38: 2013 | R38: 2000 | S38: =Q38-R38 -> 13
A39: 2011 | B39: 0.47175 | C39: 8.5 | H39: ala12 | I39: =CONCATENATE(G39,H39) -> ala12 | J39: 0.65516071 | K39: 13.5 | M39: 13.5 | P39: sad22 | Q39: 2013 | R39: 2004 | S39: =Q39-R39 -> 9
A40: 2012 | B40: 0.6054 | C40: 8.5 | G40: ala12 | H40: 2000 | I40: =CONCATENATE(G40,H40) -> ala122000 | J40: 0.613 | K40: 13.5 | L40: =L41-J41 -> 4.94075 | M40: 4.94075
...
